Workbook

Sheet À lire
A1: Export du catalogue PrestaShop (abcterroirs.com) avec les références LMB
A2: Extrait le 16/10/2026 : 464 produits du site (344 actifs, 120 désactivés), rapprochés de l'extraction LMB « ETIQUETTES_PRIX_BD_au_141026 » puis vérifiés dans le catalogue LMB en ligne (archives comprises) le 19/10/2026.
A4: Colonne « Statut réf. LMB » (le décompte ci-dessous se met à jour tout seul) :
A5: Confirmée | B5: =COUNTIF(Produits!C:C,A5) -> 88
A6: Corrigée | B6: =COUNTIF(Produits!C:C,A6) -> 81
A7: Ajoutée | B7: =COUNTIF(Produits!C:C,A7) -> 251
A8: Ajoutée, à vérifier | B8: =COUNTIF(Produits!C:C,A8) -> 5
A9: Corrigée, à vérifier | B9: =COUNTIF(Produits!C:C,A9) -> 1
A10: À vérifier | B10: =COUNTIF(Produits!C:C,A10) -> 1
A11: Introuvable dans LMB | B11: =COUNTIF(Produits!C:C,A11) -> 4
A12: Total | B12: =SUM(B5:B11) -> 431
A14: Comment les références ont été trouvées
A15: - Chaque produit a été comparé aux articles LMB par le nom (actuel et ancien nom du site), le prix TTC et la contenance, puis vérifié à la main.
A16: - Vert : référence sûre. Jaune : référence probable ou plusieurs possibles, voir la colonne Remarque. Rouge : aucun article LMB ne correspond (produit plus vendu, ou absent de LMB).
A17: - Colonne « Ancienne réf. (site) » : ce qui était renseigné sur PrestaShop, gardé pour mémoire. Les anciennes réf. sans « A- » ne sont pas des références LMB.
A18: - Plusieurs produits du site partagent parfois la même réf. LMB : LMB regroupe certains parfums ou formats (ex. Nona 20 cl, Ginger & Ginger, rhums arrangés 20 cl, places de dégustation).
A20: Autres onglets et fichiers
A21: - Onglet « Descriptions HTML » : descriptions avec la mise en forme du site. Fichier produits-prestashop.csv : même contenu que « Produits », pour un import.
A22: - Aucun code-barres (EAN) ni prix d'achat n'est renseigné sur le site. Prix TTC = prix HT × (1 + TVA), calculé dans le fichier.
A23: - Rien n'a été modifié sur le site ni dans LMB : les références du site PrestaShop restent à mettre à jour (je peux le faire sur demande).

Sheet Produits
A1: Référence LMB | B1: Ancienne réf. (site) | C1: Statut réf. LMB | D1: Libellé LMB | E1: Prix TTC LMB (€) | F1: Remarque | G1: Désignation | H1: Description courte | I1: Description longue | J1: Prix de vente HT (€) | K1: TVA | L1: Prix de vente TTC (€) | M1: Catégorie (site) | N1: Caractéristiques | O1: Poids (kg) | P1: Actif sur le site | Q1: ID PrestaShop | R1: Lien produit
A2: A-01002 | B2: A-01002 | C2: Confirmée | D2: GWENRANN LK CHOCOLAT LAIT ou NOIR FDS BIO 85g | E2: 6.9 | G2: Palets chocolat et fleur de sel bio – Gwenrann 85 g | H2: SUPERBE CHOCOLAT NOIR OU LAIT AVEC INCLUSION DE FLEUR DE SEL, LE COMPAGNON IDEAL POUR UNE PAUSE CAFÉ ! MERCI LAURENT POUR CETTE CREATION QUI EST UN DES SUCCES DU MAGASIN !! | I2: Gwenrann, Pays Blanc – ancien nom breton de la ville de Guérande. Un très fin palet de chocolat 70% de cacao au sein duquel est déposé de la fleur de sel, de Guérande bien sûr... Allergènes : traces de gluten et de fruits à coque. Création L'ATTELIER / Saint Nazaire | J2: 6.5403 | K2: 0.055 | L2: =IF(K2="","",ROUND(J2*(1+K2),2)) -> 6.9 | M2: Épicerie sucrée | N2: Glucides (g) / dont sucre (g): 31 / 30 ; Protéines (g): 7 ; Matières grasses (g) / dont acides gras saturés (g): 41 / 23 ; Energie (kJ / kcal): 2262 / 544 | O2: 0.29 | P2: Oui | Q2: 101 | R2: https://abcterroirs.com/index.php?id_product=101&controller=product
A3: A-02862 | B3: A-02862 | C3: Confirmée | D3: NOIX DE CAJOU CARAMÉLISÉES LK POIVRE PIMENT TRUFFE 110g | E3: 7.9 | G3: Noix de cajou caramélisées et salées bio 110 g | H3: ATTENTION, PRODUIT ADDICTIF DU MAGASIN, NE PAS GOUTER... C'EST TROP BON ! EMBELLISSEZ VOS APÉROS AVEC CES CAJOUS SALÉES, MERCI LAURENT... OU PAS !! | I3: La noix de cajou est un véhicule parfait pour mettre en valeur une épice, ici association noix de cajou caramélisée au fameux piment d’Espelette AOP. Le croquant de la fine couche de caramel est suivi par une imbrication d’arômes sucrés salés enveloppés par la vivacité raisonnable du piment d’Espelette. Une tuerie BIS pour l'apéro. Allergènes : traces de gluten et de fruits à coque. Création Laurent : L'ATTELIER / Saint Nazaire | J3: 7.4882 | K3: 0.055 | L3: =IF(K3="","",ROUND(J3*(1+K3),2)) -> 7.9 | M3: Autres | N3: Glucides (g) / dont sucre (g): 30 / 6 ; Protéines (g): 7 ; Matières grasses (g) / dont acides gras saturés (g): 44 / 7.8 ; Energie (kJ / kcal): 2314 / 553 | O3: 0.29 | P3: Oui | Q3: 102 | R3: https://abcterroirs.com/index.php?id_product=102&controller=product
A4: A-02862 | B4: 2871 | C4: Corrigée, à vérifier OK | D4: NOIX DE CAJOU CARAMÉLISÉES LK POIVRE PIMENT TRUFFE 110g | E4: 7.9 | F4: LMB regroupe les noix caramélisées salées sous une seule réf. | G4: Noix de cajou caramélisées et poivre de Kampot bio 110 g | H4: Attention produit addictif et original pour l'apéro, le goûter c'est succomber ! | I4: La noix de cajou est un véhicule parfait pour mettre en valeur une épice donc a été associée cette noix de cajou caramélisée au poivre de Kâmpôt AOP. Le croquant de la fine couche de caramel est suivi par une combinaison d’arômes sucrés & salés enveloppés par la tonicité des deux poivres rouge et noir... Une tuerie pour l'apéro. Allergènes : traces de gluten et de fruits à coque. Création Laurent LK / Saint Nazaire | J4: 7.49 | K4: 0.055 | L4: =IF(K4="","",ROUND(J4*(1+K4),2)) -> 7.9 | M4: Autres | N4: Glucides (g) / dont sucre (g): 30 / 6 ; Protéines (g): 7 ; Matières grasses (g) / dont acides gras saturés (g): 44 / 7.8 ; Energie (kJ / kcal): 2314 / 553 | O4: 0.29 | P4: Oui | Q4: 103 | R4: https://abcterroirs.com/index.php?id_product=103&controller=product
A5: A-02830 | B5: 2839 | C5: Corrigée | D5: QUERNONS SACHET 100g (x13) | E5: 11 | G5: Quernons d'Ardoise – sachet 100 g (x13) | H5: Les Quernons d'Ardoise, la célèbre spécialité d'Angers : une fine nougatine enrobée de chocolat bleuté, en souvenir des ardoises de l'Anjou. Sachet de 13 pièces. Parfait au goûter, avec un café, ou pour garnir un coffret gourmand. Une question ? Nos cavistes vous conseillent volontiers en boutique ou au 02 40 89 76 26. | I5: Spécialité angevine gourmande sur une base nougatine et chocolat. | J5: 10.4265 | K5: 0.055 | L5: =IF(K5="","",ROUND(J5*(1+K5),2)) -> 11 | M5: Épicerie sucrée | N5: Sel (g): 10mg ; Glucides (g) / dont sucre (g): 67 / 67 ; Protéines (g): 5 ; Matières grasses (g) / dont acides gras saturés (g): 23 / 9.2 ; Energie (kJ / kcal): 2091/499 | O5: 0.12 | P5: Oui | Q5: 109 | R5: https://abcterroirs.com/index.php?id_product=109&controller=product
A6: A-01409 | B6: 2662 | C6: Corrigée | D6: PB PETIT BEURRE 70G - Maison Suzanne | E6: 4.9 | G6: Petits beurres faits à Clisson (44) 70 g | H6: En parfum disponible : noisettes cacao / sarrasin fève de tonka / caramel salé / muroise. Très artisanal et très local, l'idéal au final ! Sachet 70g | I6: Anne-Hélène est la fondatrice de Maison Suzanne. C’est en fait sa grand-mère Suzanne, qui l’a inspirée. Elle propose dans le vignoble nantais à côté de Clisson des biscuits gourmands confectionnés avec des matières premières de qualité. A découvrir ! | J6: 4.6445 | K6: 0.055 | L6: =IF(K6="","",ROUND(J6*(1+K6),2)) -> 4.9 | M6: Biscuits | O6: 0.07 | P6: Oui | Q6: 114 | R6: https://abcterroirs.com/index.php?id_product=114&controller=product
A7: A-02604 | B7: 2613 | C7: Corrigée | D7: WHISKY HELLYERS ROAD (Tasmanie) | E7: 48.9 | F7: prix LMB 48,90 € / site 52,90 € | G7: Whisky Hellyers Road – Tasmanie | I7: Incontournable de la distillerie Hellyers Road, ce single malt est produit à partir d’orge maltée locale, produite sur l’île de Tasmanie dans le sud de l’Australie. | J7: 44.08 | K7: 0.2 | L7: =IF(K7="","",ROUND(J7*(1+K7),2)) -> 52.9 | M7: Autres | N7: Degré d'alcool: 40 ; 0,7: 0,7 | O7: 1.55 | P7: Oui | Q7: 116 | R7: https://abcterroirs.com/index.php?id_product=116&controller=product
A8: A-02562 | B8: 2571 | C8: Corrigée | D8: LA PLAGE (Melon B) - Les Trois Toits | E8: 10.5 | G8: LA PLAGE (Melon B) - Les Trois Toits | H8: Muscadet devenu un joli reflet du domaine des trois toits ! | I8: Cette cuvée de printemps est toute en fraîcheur, sur de belles notes d'agrumes. A déguster au pied levé, en toute simplicité, en pique nique, et pourquoi pas à la plage ! | J8: 8.75 | K8: 0.2 | L8: =IF(K8="","",ROUND(J8*(1+K8),2)) -> 10.5 | M8: Vins de Loire | N8: Degré d'alcool: 12 ; 0,75: 0,75 | O8: 1.4 | P8: Non | Q8: 118 | R8: https://abcterroirs.com/index.php?id_product=118&controller=product
A9: A-02455 | B9: 2464 | C9: Corrigée | D9: COUP DE FOUDRE - Fessardiere | E9: 13.9 | G9: Coup de Foudre – Domaine de la Fessardière | H9: Un vrai coup de foudre pour ce vin, outre l'image, c'est du plaisir et la nouvelle génération de muscadet plus rond et charmeur ! | I9: La robe présente une belle couleur jaune. Le nez est plaisant, à la fois fruité et minéral sur le citron et la pêche. Ce vin est équilibré, rond avec ses notes citronnées et de fleur blanche. Frais et léger, ce muscadet élevé 9 mois dans un foudre de chêne ancien saura vous surprendre. | J9: 12.4167 | K9: 0.2 | L9: =IF(K9="","",ROUND(J9*(1+K9),2)) -> 14.9 | M9: Vins de Loire | N9: Degré d'alcool: 12 ; 0,75: 0,75 | O9: 1.32 | P9: Oui | Q9: 120 | R9: https://abcterroirs.com/index.php?id_product=120&controller=product
A10: A-02454 | B10: 2463 | C10: Corrigée | D10: LA MER Muscadet - Fessardière | E10: 11.9 | G10: La Mer, muscadet bio – Domaine de la Fessardière | H10: Vin en apparence classique dans un premier temps, puis un second temps où se libèrent des notes fruitées. Bref, typicité du muscadet : vivacité et salinité, puis une finale plus aromatique, que du bonheur ! BIO et consigné !! | I10: Robe jaune pâle, nez floral et fruité, notes d’agrumes, on retrouve des parfums iodés et une touche fumée. La bouche est ronde, charnue, fruitée et acidulée. | J10: 9.9167 | K10: 0.2 | L10: =IF(K10="","",ROUND(J10*(1+K10),2)) -> 11.9 | M10: Vins de Loire | N10: Degré d'alcool: 12 ; 0,75: 0,75 | O10: 1.3 | P10: Oui | Q10: 121 | R10: https://abcterroirs.com/index.php?id_product=121&controller=product
A11: A-02321 | B11: A-02321 | C11: Confirmée | D11: CINQ-CINQ Spiced Rhum Bio - Distiloire 70cl | E11: 48.5 | G11: Rhum épicé Cinq-Cinq Spiced bio – Distiloire 70 cl | I11: Rhum ambré de dégustation, le Spiced Rhum 5.5 c’est la rencontre gourmande de l’Amérique du sud et du Val de Loire autour de 5 plantes et épices. Sa double maturation de plusieurs années en fût de Bourbon puis 5 mois en fût de vin de Loire liquoreux, lui apporte caractère et élégance. Artisanal, 100% bio et naturel, sans additif ni colorant, le Spiced Rhum 5.5 est également peu sucré (seulement 20 g/L) pour une dégustation sans fausse note ! | J11: 40.4167 | K11: 0.2 | L11: =IF(K11="","",ROUND(J11*(1+K11),2)) -> 48.5 | M11: Rhums | N11: Degré d'alcool: 40 ; 0,7: 0,7 | O11: 1.5 | P11: Oui | Q11: 122 | R11: https://abcterroirs.com/index.php?id_product=122&controller=product
A12: A-02256 | B12: A-02256 | C12: Confirmée | D12: GIN Cotswolds Dry Gin - Angleterre | E12: 56.5 | G12: Gin Cotswolds Dry Gin – Angleterre | H12: Le Cotswolds Dry Gin est un gin artisanal anglais élaboré dans la région des Cotswolds. Distillé lentement en alambic pot still et titrant 46 %, il se distingue par l’utilisation d’une forte concentration de neuf botaniques dont genièvre, lavande locale, pamplemousse rose et zestes de citron vert frais. Le nez dévoile des arômes frais et épicés d’agrumes et de coriandre. En bouche, le genièvre et le pamplemousse s’équilibrent avec des notes florales et légèrement épicées. Riche en huiles essentielles, il devient légèrement trouble avec la glace ou le tonic, offrant un Gin & Tonic intense, frais et aromatique | I12: Elaboré à partir d’un spiritueux à base de blé, ce gin est infusé par macération ou par vapeur avec des botaniques de provenance locale, à savoir de la région de Cotswolds au sud-ouest de l’Angleterre. | J12: 47.0833 | K12: 0.2 | L12: =IF(K12="","",ROUND(J12*(1+K12),2)) -> 56.5 | M12: Gins | N12: Degré d'alcool: 46 ; 0,7: 0,7 | O12: 1.5 | P12: Oui | Q12: 123 | R12: https://abcterroirs.com/index.php?id_product=123&controller=product
A13: A-02254 | B13: 2263 | C13: Corrigée | D13: RHUM NEISSON Le Rhum (blanc) | E13: 42.9 | F13: prix LMB 42,90 € | G13: Rhum Neisson Le Rhum (blanc) – Martinique | H13: Festival de cannes fraîches ! Deux paramètres expliquent ce rhum blanc complexe : un sous-sol d’origine volcanique dont se nourrissent les cannes à sucre de La Thieubert et l’influence du littoral Caraïbe sur un climat très sec et ensoleillé. Neisson est le fruit d’un long travail de maturation, au cours duquel les crus sont brassés et aérés régulièrement. | J13: 33.25 | K13: 0.2 | L13: =IF(K13="","",ROUND(J13*(1+K13),2)) -> 39.9 | M13: Martinique | N13: Degré d'alcool: 52,5 ; Volume: 70cl | O13: 1.4 | P13: Oui | Q13: 124 | R13: https://abcterroirs.com/index.php?id_product=124&controller=product
A14: A-02216 | B14: A-02216 | C14: Confirmée | D14: WHISKY ARMORIK Classic | E14: 51 | G14: Whisky Armorik Classic – Bretagne | I14: Pierre angulaire de la gamme, Armorik Classic est le fruit d’un vieillissement effectué en fûts de bourbon de différents âges. Doux, onctueux et gourmand, il met en évidence la qualité du vieillissement sur la côte bretonne et l’expertise de leur maître de chai. | J14: 42.5 | K14: 0.2 | L14: =IF(K14="","",ROUND(J14*(1+K14),2)) -> 51 | M14: Whiskies français | N14: Degré d'alcool: 46 ; 0,7: 0,7 | O14: 1.4 | P14: Oui | Q14: 125 | R14: https://abcterroirs.com/index.php?id_product=125&controller=product
A15: A-02192 | B15: 2201 | C15: Corrigée | D15: COFFRET LA NANTILLAISE V2 | E15: 35.6 | G15: Coffret La Nantillaise – Grand | H15: Coffret sans alcool, bien représentatif de Nantes et du département en sucré salé | I15: Assortiment sans alcool autour du Nantillais, sirop très naturel historique de Nantes. Composition sirop 47cl (plusieurs parfums) Salé : Rillette de poisson de Loire. Sucré : tablette de chocolat torréfié à Nantes. Petit clin d'œil avec le berlingot nantais, 200g, et aussi les petits beurre de la maison Suzanne, biscuit historique de la ville. | J15: 33.7441 | K15: 0.055 | L15: =IF(K15="","",ROUND(J15*(1+K15),2)) -> 35.6 | M15: Sélection 25 à 50€ | O15: 3.5 | P15: Oui | Q15: 126 | R15: https://abcterroirs.com/index.php?id_product=126&controller=product
A16: A-05222 | B16: 2184 | C16: Corrigée | D16: COFFRET 100% SARRASIN V2 | E16: 40.8 | G16: Coffret 100 % sarrasin – Moyen | H16: Création originale autour du sarrasin, surnommé le blé noir, avec beaucoup de créations spécifiques au magasin. Le cidre est un gros succès du magasin avec cette jolie infusion de blé noir qui parfume fortement à l'ouverture et qui s'équilibre en bouche, les autres produits prouvent toute l'harmonie sucrée et salée que peut procurer cette plante bretonne. | I16: Une sélection artisanale autour du Sarrasin à dominante salée. Cidre et crème de caramel viennent de Bretagne, les autres produits du département Loire-Atlantique. Composition : cidre Kystin au blé noir torréfié (75cl), gressins de blé noir au romarin (100g), rillettes de canard au sarrasin grillé (90g), petit beurre au sarrasin et fève de tonka (90g), crème caramel salé sarrasin (40g), tablette chocolat au sarrasin (135g) | J16: 38.673 | K16: 0.055 | L16: =IF(K16="","",ROUND(J16*(1+K16),2)) -> 40.8 | M16: Sélection 25 à 50€ | O16: 3.5 | P16: Oui | Q16: 127 | R16: https://abcterroirs.com/index.php?id_product=127&controller=product
A17: A-02989 | B17: 2161 | C17: Corrigée | D17: PATE / RILLETTES LANGOUILLE (PETIT) 90g | E17: 4.9 | G17: Pâté ou rillettes à la langouille – Labbé-Simon | H17: Pâtés ou rillettes de porc mélangées avec 20% de langouille. Belle création locale. Ici pot de 90g | I17: La langouille est un produit de charcuterie artisanale. Elle est élaborée à partir de langue de porc saumurée, fumée, enveloppée dans un boyau naturel de bœuf et cuite dans un bouillon. Dans son laboratoire situé à Saint-Malo-de-Guersac, Labbe Simon en a fait sa spécialité depuis 1982. | J17: 4.6445 | K17: 0.055 | L17: =IF(K17="","",ROUND(J17*(1+K17),2)) -> 4.9 | M17: Terre | O17: 0.1 | P17: Oui | Q17: 128 | R17: https://abcterroirs.com/index.php?id_product=128&controller=product
B18: 2156 | C18: Introuvable dans LMB | G18: COFFRET ASSORTIMENT MARIN SANS ALCOOL | H18: Sélections de produits régionaux issus de la pêche de Loire ou bien de l'Atlantique. Assortiment joliment varié puisqu'on trouve une boite de sardines millésimées, tartares d'algues ou salicornes, fleur de sel de la presqu'ile de Guérande, soupe et rillettes de poissons. | I18: Rillettes de poisson de Loire - Claude Janin. Pêche traditionnelle de poissons sauvages et élaboration artisanale des recettes. 780g Soupe de poisson de l'Atlantique - Bernard Marot. Un ancien poissonnier nantais qui aujourd"hui possède sa propre conserverie en Loire Atlantique. 80g Tartare d'algues - Christine Le Tennier. Des algues bretonnes pour l'élaboration de recettes gourmandes et originales. 90g Fleur de sel de la presqu'ile de Guérande - 100g rillettes de poisson de l'Atlantique - Bernard Marot. 100g Sardines millésimées - La perles des dieux. Dessin de Delphine Cossais ou de Coralie Joulin. 115g | J18: 38.8626 | K18: 0.055 | L18: =IF(K18="","",ROUND(J18*(1+K18),2)) -> 41 | M18: Sélection 25 à 50€ | O18: 3.5 | P18: Non | Q18: 129 | R18: https://abcterroirs.com/index.php?id_product=129&controller=product
A19: A-02146 | B19: 2155 | C19: Corrigée | D19: LES GRALETTES (Fié Gris) - Eric Chevalier | E19: 14.5 | G19: Les Gralettes (fié gris) – Éric Chevalier | H19: Spécialiste du Fié Gris, Eric Chevalier nous offre une cuvée BIO idéale pour les cuisines asiatique ou exotiques ! | I19: Appelé aussi sauvignon rose, le cépage était présent sur le Val de Loire et le Haut-Poitou avant la crise phylloxérique, mais disparaît pratiquement au profit du sauvignon blanc, son plus proche cousin. Désormais, seuls quelques trop rares vignerons pratiquent à nouveau ce cépage afin de bénéficier de ses possibilités aromatiques. | J19: 12.0833 | K19: 0.2 | L19: =IF(K19="","",ROUND(J19*(1+K19),2)) -> 14.5 | M19: Vins de Loire | N19: Degré d'alcool: 13,5 ; 0,75: 0,75 | O19: 1.4 | P19: Oui | Q19: 130 | R19: https://abcterroirs.com/index.php?id_product=130&controller=product
A20: A-02114 | B20: 2123 | C20: Corrigée | D20: COFFRET NANTES SURPRENANT V2 | E20: 48 | G20: Coffret Nantes surprenant – Moyen | H20: Sélections Nantaises mais surprenantes avec quelques-uns de nos meilleurs produits. Composition :Diablotine, apéritif composé de muscadet, de rhum et de sirop de fruit originaux (75cl). Salé : Saucisson fleur de sel local, des rillettes de poissons de Loire, fondantes en bouche, travaillée sur le filet du poisson et artisanal et des petits beurre salés artisanaux. Sucré : Des raisins secs macérés dans un muscadet vendanges tardives et enrobés de chocolat noir. Petit clin d'œil sucré avec une confiture de muroise®, fruit emblématique du vignoble nantais issu d'un hybride naturel de mûre et de framboise. | I20: Diablotine (75cl). Saucisson fleur de sel local, des rillettes de poissons de Loire Janin 100g , sablés Maison Suzanne 80g. Des raisins secs enrobés de chocolat noir 90g. Une confiture de muroise® 45g. | J20: 45.4976 | K20: 0.055 | L20: =IF(K20="","",ROUND(J20*(1+K20),2)) -> 48 | M20: Sélection 25 à 50€ | O20: 3.5 | P20: Oui | Q20: 131 | R20: https://abcterroirs.com/index.php?id_product=131&controller=product
A21: A-01985 | B21: 1994 | C21: Corrigée | D21: COFFRET 100% NANTAISES V2 | E21: 53.8 | G21: Coffret 100 % Nantaises – Moyen | H21: Sélection de produits artisanaux sucrés salés et créés uniquement par des Femmes nantaises : Bérangère, Christine, Estelle, Magali, Sandrine, Anne-Hélène, , Aurore, Véronique, Charlotte. Best of de notre magasin très révélateur du départemetn Loire-Atlantique : muscadet, bière, biscuits, légumes, rillettes... | I21: Composition : Rillettes de canard les délices du petit gué (80g) Tartinable de légumes Papilles et petits plats (90g) Confiture de muroise (220g) Le sablé de la tarte bauloise (180g) Petit beurre artisanal à la fleur de sel fabriqué à Clisson par Maison Suzanne (80g) ,Vin blanc " La Mer " Domaine de la Fessardière (75cl) Bière de charlotte (75cl) | J21: 44.8333 | K21: 0.2 | L21: =IF(K21="","",ROUND(J21*(1+K21),2)) -> 53.8 | M21: Sélection plus de 50€ | O21: 4.5 | P21: Oui | Q21: 132 | R21: https://abcterroirs.com/index.php?id_product=132&controller=product
A22: A-01978 | B22: 1987 | C22: Corrigée | D22: COFFRET KIR NANTAIS v1 | E22: 49.9 | G22: Coffret Kir nantais | H22: Une collection "Made In Nantes" avec des spécialités typiques. Muscadet et sirop le nantillais sont associés pour former le kir 100% Nantais et accompagnés de déclinaisons salées autour du muscadet : saucisse et canard et de quelques autres typicités dont le dessert historique au rhum, le gâteau nantais. | I22: Composition : Muscadet fruité et minéral, par la maison Cormerais, idéal pour l'apéritif et les crustacés à marier avec Nantillais : sirop sans alcool qui existe depuis plus de 20 ans. Salé : rillettes de canard au muscadet par Bérangère 100g, saucisse sèche au muscadet par le petit Landréen 150g environ, fleur de sel de la presqu'ile de Guérande 100g. Sucré : sachet de Berlingots aux fruits 200g et gâteau nantais 130g | J22: 47.2986 | K22: 0.055 | L22: =IF(K22="","",ROUND(J22*(1+K22),2)) -> 49.9 | M22: Sélection 25 à 50€ | O22: 4.5 | P22: Oui | Q22: 133 | R22: https://abcterroirs.com/index.php?id_product=133&controller=product
A23: A-05447 | B23: 1986 | C23: Corrigée | D23: COFFRET LULU LA NANTAISE V2 | E23: 39 | G23: Coffret Lulu la Nantaise | H23: LULU la nantaise, elle en buvait au petit-déjeuner... de la liqueur de petit beurre ? | I23: Déclinaison autour du petit beurre avec des biscuits faits maison, sa boite, une liqueur au goût de biscuit ainsi qu'une pâte à tartiner. Composition : - Liqueur au délicieux goût de biscuit à déguster seul ou en nappage (20cl) - Petit beurre fabriqué avec amour à Clisson (44) au bon goût de beurre frais (70g) - Boite à l'effigie du plus célèbre petit écolier du monde - Dessous de verre LULU - tablette chocolat petit beurre | J23: 32.5 | K23: 0.2 | L23: =IF(K23="","",ROUND(J23*(1+K23),2)) -> 39 | M23: Sélection 25 à 50€ | O23: 2.5 | P23: Oui | Q23: 134 | R23: https://abcterroirs.com/index.php?id_product=134&controller=product
A24: A-01939 | B24: A-01939 | C24: Confirmée | D24: WHISKY NIKKA From The Barrel (blend) JAPON | E24: 51.5 | G24: Whisky Nikka From The Barrel (blend) – Japon | I24: Bouteille iconique du groupe Nikka, le From The Barrel représente à lui seul la maîtrise de l’assemblage nippon : puissance, finesse et équilibre. Bluffant à plus d’un titre, ce blend aux 100 whiskies confondrait plus d’un amateur qui ne jure que par les single malts. Ici, les fruits bien mûrs, voire confits donnent le change à des épices de caractère. Le tout faisant passer les 51,4% d’alcool (presque) comme une lettre à la poste … L’art de l’assemblage avec un grand A | J24: 42.9167 | K24: 0.2 | L24: =IF(K24="","",ROUND(J24*(1+K24),2)) -> 51.5 | M24: Whiskies japonais | N24: Degré d'alcool: 51,4 ; 0,5: 0,5 | O24: 1 | P24: Oui | Q24: 136 | R24: https://abcterroirs.com/index.php?id_product=136&controller=product
A25: A-01936 | B25: A-01936 | C25: Confirmée | D25: WHISKY NIKKA Coffey Grain (single grain) JAPON | E25: 59.9 | G25: Whisky Nikka Coffey Grain (single grain) – Japon | I25: Elaboré à partir d’une majorité de maïs provenant des alambics « Coffey », ce single grain nous offre un aperçu des whiskies de grain qui forment la base de tous les blends de la maison Nikka, au style particulièrement suave et charmeur. | J25: 49.92 | K25: 0.2 | L25: =IF(K25="","",ROUND(J25*(1+K25),2)) -> 59.9 | M25: Whiskies japonais | N25: Degré d'alcool: 45 ; 0,7: 0,7 | P25: Oui | Q25: 137 | R25: https://abcterroirs.com/index.php?id_product=137&controller=product
A26: A-01927 | B26: A-01927 | C26: Confirmée | D26: WHISKY KORNOG ROC'H HIR (tourbé) | E26: 71.9 | G26: Whisky Kornog Roc'h Hir (tourbé) – Bretagne | I26: Whisky tourbé, mais d'une grande finesse, élevé en fut de bourbon. Meilleur Whisky Européen en 2016 par Jim MURRAY Liquid Gold Award 94/100 - Whisky Bible 2020 | J26: 59.9167 | K26: 0.2 | L26: =IF(K26="","",ROUND(J26*(1+K26),2)) -> 71.9 | M26: Whiskies français | N26: Degré d'alcool: 46% ; Volume: 70cl | O26: 1.4 | P26: Oui | Q26: 138 | R26: https://abcterroirs.com/index.php?id_product=138&controller=product
A27: A-01895 | B27: A-01895 | C27: Confirmée | D27: WHISKY BRETON EDDU Brocéliande - PUR BLE NOIR | E27: 59.9 | G27: Whisky Eddu Brocéliande pur blé noir – Bretagne | H27: Fondée par la famille Le Lay qui était au départ dans les années 1920 des distillateurs ambulants et en 1986 ils créèrent "La distillerie des Menhirs". La distillerie familiale commença la réalisation du whisky en 1999 avec le premier du monde uniquement de blé noir. | I27: Vieilli d’abord 5 ans en fût de chêne français du Limousin, EDDU Silver Brocéliande achève sa maturation en fût de chêne neuf de la forêt de Brocéliande. Nez : boisé - floral - fruits secs Bouche : boisé - vanille - fruitées Finale : longue et raffinée | J27: 49.9167 | K27: 0.2 | L27: =IF(K27="","",ROUND(J27*(1+K27),2)) -> 59.9 | M27: Whiskies français | N27: Degré d'alcool: 42 ; Volume: 0.70 | O27: 1.7 | P27: Oui | Q27: 139 | R27: https://abcterroirs.com/index.php?id_product=139&controller=product
A28: A-01894 | B28: A-01894 | C28: Confirmée | D28: WHISKY BRETON ED GWENN (single malt) - Eddu | E28: 61.5 | G28: Whisky Eddu Ed Gwenn (single malt) – Bretagne | H28: Fondée par la famille Le Lay qui était au départ dans les années 1920 des distillateurs ambulants et en 1986 ils créèrent "La distillerie des Menhirs". La distillerie familiale commença la réalisation du whisky en 1999 avec le premier du monde uniquement de blé noir. | I28: Obtenu par distillation d’orge uniquement, Ed Gwenn est vieilli pendant plus de 4 ans en fûts de chêne français et américain. Par analogie avec Eddu qui signifie blé noir, Ed Gwenn signifie céréale blanche en breton. Nez : bananes flambées - fruits exotiques mûrs Bouche : litchi - pêche Finale : douce et élégante | J28: 51.25 | K28: 0.2 | L28: =IF(K28="","",ROUND(J28*(1+K28),2)) -> 61.5 | M28: Whiskies français | N28: Degré d'alcool: 45 ; Volume: 0.70 | O28: 1.6 | P28: Oui | Q28: 140 | R28: https://abcterroirs.com/index.php?id_product=140&controller=product
A29: A-01891 | B29: 1900 | C29: Corrigée | D29: WHISKY BRETON EDDU Gold (10ans) | E29: 81.5 | G29: Whisky Eddu Gold 10 ans – Bretagne | H29: Fondée par la famille Le Lay qui était au départ dans les années 1920 des distillateurs ambulants et en 1986 ils créèrent "La distillerie des Menhirs". La distillerie familiale commença la réalisation du whisky en 1999 avec le premier du monde uniquement de blé noir. | I29: Whisky vieillit 10 ans en fût de chêne français Nez : bois de chêne torréfié - épices Bouche : fruits pâtissiers - miel Finale : fruité - épices | J29: 67.9167 | K29: 0.2 | L29: =IF(K29="","",ROUND(J29*(1+K29),2)) -> 81.5 | M29: Whiskies français | N29: Degré d'alcool: 43 ; Volume: 0.70 | P29: Oui | Q29: 141 | R29: https://abcterroirs.com/index.php?id_product=141&controller=product
A30: A-01890 | B30: A-01890 | C30: Confirmée | D30: WHISKY BRETON EDDU Silver (100% blé noir) | E30: 52.9 | G30: Whisky Eddu Silver 100 % blé noir – Bretagne | H30: Fondée par la famille Le Lay qui était au départ dans les années 1920 des distillateurs ambulants et en 1986 ils créèrent "La distillerie des Menhirs". La distillerie familiale commença la réalisation du whisky en 1999 avec le premier du monde uniquement de blé noir. | I30: Vieilli 5 ans en fût de chêne français ayant contenu du Cognac, EDDU Silver l’original est la première édition de la gamme EDDU. Nez : agrumes - fruits frais - rose - bruyère bouche : pomme - épice - boisé très fin Finale : fraîche - fruité - équilibré | J30: 41.5833 | K30: 0.2 | L30: =IF(K30="","",ROUND(J30*(1+K30),2)) -> 49.9 | M30: Whiskies français | N30: Degré d'alcool: 43 ; Volume: 0.70 | O30: 1.7 | P30: Oui | Q30: 142 | R30: https://abcterroirs.com/index.php?id_product=142&controller=product
A31: A-01760 | B31: 1769 | C31: Corrigée | D31: TÊTE DE LARD (Cab franc) - Manoir de la Tête Rouge | E31: 16.9 | G31: Tête de Lard (cabernet franc) – Manoir de la Tête Rouge | H31: Découvrez une appellation, un terroir et un vigneron au travers de cette cuvée en BIO DYNAMIE. 100% cabernet franc. 100% racé ! | I31: Robe rouge Grenat, note de sous bois de torréfaction légèrement animal. La bouche est soyeuse vive complexe et riche. Les tannins sont présents granuleux sans astringence. La texture est crayeuse et la final est longue. Potentiel de garde de 10 ans, à 5 ans près ! | J31: 14.0833 | K31: 0.2 | L31: =IF(K31="","",ROUND(J31*(1+K31),2)) -> 16.9 | M31: Vins de Loire | N31: Degré d'alcool: 14 ; 0,75: 0,75 | O31: 1.4 | P31: Oui | Q31: 143 | R31: https://abcterroirs.com/index.php?id_product=143&controller=product
A32: A-01759 | B32: 1768 | C32: Corrigée | D32: TÊTE D'ANGE (Chenin) - Manoir de la Tête Rouge | E32: 15.5 | G32: TÊTE D'ANGE (Chenin) - Manoir Tête Rouge | H32: Saumur blanc en biodynamie, élégance et terroir ! Un grand vigneron ! Vin blanc agréablement polyvalent : viande blanche, fromage, apéro... | I32: Un joli chenin sur les terroirs de craies de Saumur. Le nez est sur la fleur blanche, la maturité du chenin est intense, des notes d’agrumes arrivent en final. En bouche, beaucoup de gras fait croire à du sucre résiduel mais le vin est sec. | J32: 12.9167 | K32: 0.2 | L32: =IF(K32="","",ROUND(J32*(1+K32),2)) -> 15.5 | M32: Vins de Loire | N32: Degré d'alcool: 14 ; 0,75: 0,75 | O32: 1.4 | P32: Non | Q32: 144 | R32: https://abcterroirs.com/index.php?id_product=144&controller=product
A33: A-02971 | B33: 1756 | C33: Corrigée | D33: RILLETTES CANARD de BERANGERE 180G | E33: 8.9 | G33: Rillettes de canard – Délices du Petit Gué 180 g | H33: Création locale et artisanale de Bérangère vers St Nazaire. Top qualité ! 180g ici au muscadet, existe aussi au sarrasin et muroise. | I33: Petite entreprise artisanale, LES DELICES DU PETIT GUE est située à Frossay au sud-ouest de Nantes. Bérangère valorise les matières premières locales : canards élevés dans les communes alentour, Muscadet et Gros Plant du vignoble nantais, Coteaux du Layon, Muroise de Vallet et sel de Guérande. | J33: 8.436 | K33: 0.055 | L33: =IF(K33="","",ROUND(J33*(1+K33),2)) -> 8.9 | M33: Épicerie salée | P33: Oui | Q33: 145 | R33: https://abcterroirs.com/index.php?id_product=145&controller=product
A34: A-02968 | B34: 1755 | C34: Corrigée | D34: RILLETTES CANARD de BERANGERE 100G | E34: 5.9 | G34: Rillettes de canard – Délices du Petit Gué 100 g | H34: Petite entreprise artisanale, LES DELICES DU PETIT GUE est située à Frossay au sud-ouest de Nantes. Bérangère valorise les matières premières locales : canards élevés dans les communes alentour, Muscadet et Gros Plant du vignoble nantais, Coteaux du Layon, Muroise de Vallet et sel de Guérande. | J34: 5.5924 | K34: 0.055 | L34: =IF(K34="","",ROUND(J34*(1+K34),2)) -> 5.9 | M34: Épicerie salée | O34: 0.2 | P34: Oui | Q34: 146 | R34: https://abcterroirs.com/index.php?id_product=146&controller=product
A35: A-01739 | B35: 1748 | C35: Corrigée | D35: TERRINE DE PORC 85G Papilles et Petits Plats PPP | E35: 5.9 | G35: Terrine de porc – Papilles et Petits Plats 85 g | I35: « Papilles et Petits Plats » est née en 2009 grâce aux délicieuses terrines que cuisinaient ses aïeuls. Depuis, Christine concocte pour vous tous les jours des terrines, des tartinables et des chutneys. Et bien sûr, les conserves « Papilles et Petits Plats » sont des produits artisanaux, locaux, sans additifs et de grande qualité ! Produits Made In Nantes. | J35: 5.59 | K35: 0.055 | L35: =IF(K35="","",ROUND(J35*(1+K35),2)) -> 5.9 | M35: Épicerie salée | O35: 0.2 | P35: Oui | Q35: 147 | R35: https://abcterroirs.com/index.php?id_product=147&controller=product
A36: A-03195 | B36: 1730 | C36: Corrigée | D36: TARTINABLE DE LEGUMES PAPILLES ET PETITS PLATS 90g PPP | E36: 5.9 | G36: Tartinables de légumes – Papilles et Petits Plats | I36: « Papilles et Petits Plats » est née en 2009 grâce aux délicieuses terrines que cuisinaient ses aïeuls. Depuis, Christine concocte pour vous tous les jours des terrines, des tartinables et des chutneys. Et bien sûr, les conserves « Papilles et Petits Plats » sont des produits artisanaux, locaux, sans additifs et de grande qualité ! Produits Made In Nantes. | J36: 5.5924 | K36: 0.055 | L36: =IF(K36="","",ROUND(J36*(1+K36),2)) -> 5.9 | M36: Végétarien | P36: Oui | Q36: 148 | R36: https://abcterroirs.com/index.php?id_product=148&controller=product
A37: A-03675 | B37: 1575 | C37: Corrigée | D37: RJA RILLETTES POISSON LOIRE de CLAUDE JANIN 100g | E37: 5.9 | G37: RILLETTES POISSONS DE LOIRE Claude janin | I37: Claude Janin, artisan pêcheur basé à St-Juline-de-Concelles, prépare des terrines et des rillettes à base des poissons qu'il a lui même pêchés, produits qui sont labellisés « poisson sauvage du bassin de la Loire », ce qui assure la traçabilité sur la date et le lieu de pêche. Parfum : brochet beurre blanc, anguilles curé nantais, silure tomate... | J37: 5.5924 | K37: 0.055 | L37: =IF(K37="","",ROUND(J37*(1+K37),2)) -> 5.9 | M37: Épicerie salée | O37: 0.2 | P37: Non | Q37: 149 | R37: https://abcterroirs.com/index.php?id_product=149&controller=product
A38: A-01546 | B38: 1555 | C38: Corrigée | D38: RHUM HAMPDEN 8 ans (Jamaïque) | E38: 78.9 | G38: RHUM HAMPDEN 8 ans - Jamaïque | I38: Ce Hampden 8 ans, digne héritier des "Stinking Rums" Jamaïcains, est un savoureux mélange de fruits mûrs, d'épices douces et de notes finement boisées. Son profil intense et ses arômes très prononcés lui confèrent un caractère authentique et naturel. | J38: 65.75 | K38: 0.2 | L38: =IF(K38="","",ROUND(J38*(1+K38),2)) -> 78.9 | M38: Caraïbes | N38: Degré d'alcool: 46 ; 0,7: 0,7 | O38: 1.6 | P38: Non | Q38: 150 | R38: https://abcterroirs.com/index.php?id_product=150&controller=product
A39: A-01509 | B39: 1518 | C39: Corrigée | D39: QUERNONS BOITE 60g (x8) | E39: 7.9 | G39: Quernons d'Ardoise – boîte 60 g (x8) | H39: Les Quernons d'Ardoise, la célèbre spécialité d'Angers : une fine nougatine enrobée de chocolat bleuté, en souvenir des ardoises de l'Anjou. Boîte de 8 pièces, jolie à offrir. Parfait au goûter, avec un café, ou pour garnir un coffret gourmand. Une question ? Nos cavistes vous conseillent volontiers en boutique ou au 02 40 89 76 26. | I39: Spécialité angevine gourmande sur une base nougatine et chocolat. | J39: 7.4882 | K39: 0.055 | L39: =IF(K39="","",ROUND(J39*(1+K39),2)) -> 7.9 | M39: Épicerie sucrée | N39: Sel (g): 10mg ; Glucides (g) / dont sucre (g): 67 / 67 ; Protéines (g): 5 ; Matières grasses (g) / dont acides gras saturés (g): 23 / 9.2 ; Energie (kJ / kcal): 2091/499 | O39: 0.12 | P39: Oui | Q39: 152 | R39: https://abcterroirs.com/index.php?id_product=152&controller=product
A40: A-01507 | B40: 1516 | C40: Corrigée | D40: QUERNONS BOITE 245g (x32) | E40: 29.9 | G40: QUERNONS BOITE 245g (x32) | I40: Spécialité angevine gourmande sur une base nougatine et chocolat. | J40: 28.3412 | K40: 0.055 | L40: =IF(K40="","",ROUND(J40*(1+K40),2)) -> 29.9 | M40: Épicerie sucrée | N40: Sel (g): 10mg ; Glucides (g) / dont sucre (g): 67 / 67 ; Protéines (g): 5 ; Matières grasses (g) / dont acides gras saturés (g): 23 / 9.2 ; Energie (kJ / kcal): 2091 / 499 | O40: 0.12 | P40: Non | Q40: 153 | R40: https://abcterroirs.com/index.php?id_product=153&controller=product
...

Sheet Descriptions HTML
A1: Référence LMB | B1: Désignation | C1: Description courte (HTML) | D1: Description longue (HTML) | E1: ID PrestaShop
A2: A-01002 | B2: Palets chocolat et fleur de sel bio – Gwenrann 85 g | C2: <p><strong>SUPERBE CHOCOLAT NOIR OU LAIT AVEC INCLUSION DE FLEUR DE SEL, LE COMPAGNON IDEAL POUR UNE PAUSE CAFÉ !</strong></p> <p><strong>MERCI LAURENT POUR CETTE CREATION QUI EST UN DES SUCCES DU MAGASIN !!</strong></p> | D2: <p>Gwenrann, Pays Blanc – ancien nom breton de la ville de Guérande. Un très fin palet de chocolat 70% de cacao au sein duquel est déposé de la fleur de sel, de Guérande bien sûr... Allergènes : traces de gluten et de fruits à coque. Création L'ATTELIER / Saint Nazaire</p> | E2: 101
A3: A-02862 | B3: Noix de cajou caramélisées et salées bio 110 g | C3: <p><strong>ATTENTION, PRODUIT ADDICTIF DU MAGASIN, NE PAS GOUTER... C'EST TROP BON ! </strong></p> <p><strong>EMBELLISSEZ VOS APÉROS AVEC CES CAJOUS SALÉES, MERCI LAURENT... OU PAS !!</strong></p> | D3: <p>La noix de cajou est un véhicule parfait pour mettre en valeur une épice, ici association noix de cajou caramélisée au fameux piment d’Espelette AOP. Le croquant de la fine couche de caramel est suivi par une imbrication d’arômes sucrés salés enveloppés par la vivacité raisonnable du piment d’Espelette. Une tuerie BIS pour l'apéro. Allergènes : traces de gluten et de fruits à coque. Création Laurent : L'ATTELIER / Saint Nazaire</p> | E3: 102
A4: A-02862 | B4: Noix de cajou caramélisées et poivre de Kampot bio 110 g | C4: <p><strong>Attention produit addictif et original pour l'apéro, le goûter c'est succomber !</strong></p> | D4: <p>La noix de cajou est un véhicule parfait pour mettre en valeur une épice donc a été associée cette noix de cajou caramélisée au poivre de Kâmpôt AOP. Le croquant de la fine couche de caramel est suivi par une combinaison d’arômes sucrés &amp; salés enveloppés par la tonicité des deux poivres rouge et noir... Une tuerie pour l'apéro. Allergènes : traces de gluten et de fruits à coque. Création Laurent LK / Saint Nazaire</p> | E4: 103
A5: A-02830 | B5: Quernons d'Ardoise – sachet 100 g (x13) | C5: <p>Les Quernons d'Ardoise, la célèbre spécialité d'Angers : une fine nougatine enrobée de chocolat bleuté, en souvenir des ardoises de l'Anjou. Sachet de 13 pièces.</p> <p>Parfait au goûter, avec un café, ou pour garnir un coffret gourmand.</p> <p>Une question ? Nos cavistes vous conseillent volontiers en boutique ou au 02 40 89 76 26.</p> | D5: <p>Spécialité angevine gourmande sur une base nougatine et chocolat.</p> | E5: 109
A6: A-01409 | B6: Petits beurres faits à Clisson (44) 70 g | C6: <p><strong>En parfum disponible : noisettes cacao / sarrasin fève de tonka / caramel salé / muroise. Très artisanal et très local, l'idéal au final ! Sachet 70g</strong></p> | D6: <p>Anne-Hélène est la fondatrice de Maison Suzanne. C’est en fait sa grand-mère Suzanne, qui l’a inspirée. Elle propose dans le vignoble nantais à côté de Clisson des biscuits gourmands confectionnés avec des matières premières de qualité. A découvrir !</p> | E6: 114
A7: A-02604 | B7: Whisky Hellyers Road – Tasmanie | D7: Incontournable de la distillerie Hellyers Road, ce single malt est produit à partir d’orge maltée locale, produite sur l’île de Tasmanie dans le sud de l’Australie. | E7: 116
A8: A-02562 | B8: LA PLAGE (Melon B) - Les Trois Toits | C8: <p><strong>Muscadet devenu un joli reflet du domaine des trois toits ! </strong></p> | D8: <p>Cette cuvée de printemps est toute en fraîcheur, sur de belles notes d'agrumes. A déguster au pied levé, en toute simplicité, en pique nique, et pourquoi pas à la plage !</p> | E8: 118
A9: A-02455 | B9: Coup de Foudre – Domaine de la Fessardière | C9: <p><strong>Un vrai coup de foudre pour ce vin, outre l'image, c'est du plaisir et la nouvelle génération de muscadet plus rond et charmeur !</strong></p> | D9: <p>La robe présente une belle couleur jaune. Le nez est plaisant, à la fois fruité et minéral sur le citron et la pêche. Ce vin est équilibré, rond avec ses notes citronnées et de fleur blanche. Frais et léger, ce muscadet élevé 9 mois dans un foudre de chêne ancien saura vous surprendre.</p> | E9: 120
A10: A-02454 | B10: La Mer, muscadet bio – Domaine de la Fessardière | C10: <p>Vin en apparence classique dans un premier temps, puis un second temps où se libèrent des notes fruitées.</p> <p>Bref, typicité du muscadet : vivacité et salinité, puis une finale plus aromatique, que du bonheur ! BIO et consigné !!</p> | D10: <p>Robe jaune pâle, nez floral et fruité, notes d’agrumes, on retrouve des parfums iodés et une touche fumée. La bouche est ronde, charnue, fruitée et acidulée.</p> | E10: 121
A11: A-02321 | B11: Rhum épicé Cinq-Cinq Spiced bio – Distiloire 70 cl | D11: <p>Rhum ambré de dégustation, le Spiced Rhum 5.5 c’est la rencontre gourmande de l’Amérique du sud et du Val de Loire autour de 5 plantes et épices. Sa double maturation de plusieurs années en fût de Bourbon puis 5 mois en fût de vin de Loire liquoreux, lui apporte caractère et élégance. Artisanal, 100% bio et naturel, sans additif ni colorant, le Spiced Rhum 5.5 est également peu sucré (seulement 20 g/L) pour une dégustation sans fausse note !</p> | E11: 122
A12: A-02256 | B12: Gin Cotswolds Dry Gin – Angleterre | C12: <p>Le Cotswolds Dry Gin est un gin artisanal anglais élaboré dans la région des Cotswolds. Distillé lentement en alambic pot still et titrant 46 %, il se distingue par l’utilisation d’une forte concentration de neuf botaniques dont genièvre, lavande locale, pamplemousse rose et zestes de citron vert frais.</p> <p>Le nez dévoile des arômes frais et épicés d’agrumes et de coriandre.</p> <p>En bouche, le genièvre et le pamplemousse s’équilibrent avec des notes florales et légèrement épicées. Riche en huiles essentielles, il devient légèrement trouble avec la glace ou le tonic, offrant un Gin &amp; Tonic intense, frais et aromatique</p> | D12: <p>Elaboré à partir d’un spiritueux à base de blé, ce gin est infusé par macération ou par vapeur avec des botaniques de provenance locale, à savoir de la région de Cotswolds au sud-ouest de l’Angleterre.</p> | E12: 123
A13: A-02254 | B13: Rhum Neisson Le Rhum (blanc) – Martinique | C13: <p>Festival de cannes fraîches ! Deux paramètres expliquent ce rhum blanc complexe : un sous-sol d’origine volcanique dont se nourrissent les cannes à sucre de La Thieubert et l’influence du littoral Caraïbe sur un climat très sec et ensoleillé. Neisson est le fruit d’un long travail de maturation, au cours duquel les crus sont brassés et aérés régulièrement.</p> | E13: 124
A14: A-02216 | B14: Whisky Armorik Classic – Bretagne | D14: <p>Pierre angulaire de la gamme, Armorik Classic est le fruit d’un vieillissement effectué en fûts de bourbon de différents âges. Doux, onctueux et gourmand, il met en évidence la qualité du vieillissement sur la côte bretonne et l’expertise de leur maître de chai.</p> | E14: 125
A15: A-02192 | B15: Coffret La Nantillaise – Grand | C15: <p><strong>Coffret sans alcool, bien représentatif de Nantes et du département en sucré salé</strong></p> | D15: <p>Assortiment sans alcool autour du Nantillais, sirop très naturel historique de Nantes. Composition sirop 47cl (plusieurs parfums) Salé : Rillette de poisson de Loire. Sucré : tablette de chocolat torréfié à Nantes. Petit clin d'œil avec le berlingot nantais, 200g, et aussi les petits beurre de la maison Suzanne, biscuit historique de la ville.</p> | E15: 126
A16: A-05222 | B16: Coffret 100 % sarrasin – Moyen | C16: <p><strong>Création originale autour du sarrasin, surnommé le blé noir, avec beaucoup de créations spécifiques au magasin. Le cidre est un gros succès du magasin avec cette jolie infusion de blé noir qui parfume fortement à l'ouverture et qui s'équilibre en bouche, les autres produits prouvent toute l'harmonie sucrée et salée que peut procurer cette plante bretonne.</strong></p> | D16: <p>Une sélection artisanale autour du Sarrasin à dominante salée. Cidre et crème de caramel viennent de Bretagne, les autres produits du département Loire-Atlantique.</p> <p>Composition : cidre Kystin au blé noir torréfié (75cl), gressins de blé noir au romarin (100g), rillettes de canard au sarrasin grillé (90g), petit beurre au sarrasin et fève de tonka (90g), crème caramel salé sarrasin (40g), tablette chocolat au sarrasin (135g)</p> | E16: 127
A17: A-02989 | B17: Pâté ou rillettes à la langouille – Labbé-Simon | C17: <p><strong>Pâtés ou rillettes de porc mélangées avec 20% de langouille. Belle création locale. Ici pot de 90g</strong></p> | D17: <p>La langouille est un produit de charcuterie artisanale. Elle est élaborée à partir de langue de porc saumurée, fumée, enveloppée dans un boyau naturel de bœuf et cuite dans un bouillon. Dans son laboratoire situé à Saint-Malo-de-Guersac, Labbe Simon en a fait sa spécialité depuis 1982.</p> | E17: 128
B18: COFFRET ASSORTIMENT MARIN SANS ALCOOL | C18: <p><b>Sélections de produits régionaux issus de la pêche de Loire ou bien de l'Atlantique. Assortiment joliment varié puisqu'on trouve une boite de sardines millésimées, tartares d'algues ou salicornes, fleur de sel de la presqu'ile de Guérande, soupe et rillettes de poissons.</b></p> | D18: <p>Rillettes de poisson de Loire - Claude Janin. Pêche traditionnelle de poissons sauvages et élaboration artisanale des recettes. 780g Soupe de poisson de l'Atlantique - Bernard Marot. Un ancien poissonnier nantais qui aujourd"hui possède sa propre conserverie en Loire Atlantique. 80g Tartare d'algues - Christine Le Tennier. Des algues bretonnes pour l'élaboration de recettes gourmandes et originales. 90g Fleur de sel de la presqu'ile de Guérande - 100g rillettes de poisson de l'Atlantique - Bernard Marot. 100g Sardines millésimées - La perles des dieux. Dessin de Delphine Cossais ou de Coralie Joulin. 115g</p> | E18: 129
A19: A-02146 | B19: Les Gralettes (fié gris) – Éric Chevalier | C19: <p><strong>Spécialiste du Fié Gris, Eric Chevalier nous offre une cuvée BIO idéale pour les cuisines asiatique ou exotiques !</strong></p> | D19: <p>Appelé aussi sauvignon rose, le cépage était présent sur le Val de Loire et le Haut-Poitou avant la crise phylloxérique, mais disparaît pratiquement au profit du sauvignon blanc, son plus proche cousin. Désormais, seuls quelques trop rares vignerons pratiquent à nouveau ce cépage afin de bénéficier de ses possibilités aromatiques.</p> | E19: 130
A20: A-02114 | B20: Coffret Nantes surprenant – Moyen | C20: <p><span style="background-color:#ffffff;"><span style="color:#666666;font-family:Roboto, sans-serif;"><span style="font-size:14px;letter-spacing:0.5px;">Sélections Nantaises mais surprenantes avec quelques-uns de nos meilleurs produits. Composition :Diablotine, apéritif composé de muscadet, de rhum et de sirop de fruit originaux (75cl). Salé : Saucisson fleur de sel local, des rillettes de poissons de Loire, fondantes en bouche, travaillée sur le filet du poisson et artisanal et des petits beurre salés artisanaux. Sucré : Des raisins secs macérés dans un muscadet vendanges tardives et enrobés de chocolat noir. Petit clin d'œil sucré avec une confiture de muroise®, fruit emblématique du vignoble nantais issu d'un hybride naturel de mûre et de framboise.</span></span></span></p> | D20: <p>Diablotine (75cl). Saucisson fleur de sel local, des rillettes de poissons de Loire Janin 100g , sablés Maison Suzanne 80g. Des raisins secs enrobés de chocolat noir 90g. Une confiture de muroise® 45g.</p> | E20: 131
A21: A-01985 | B21: Coffret 100 % Nantaises – Moyen | C21: <p><strong>Sélection de produits artisanaux sucrés salés et créés uniquement par des Femmes nantaises : Bérangère, Christine, Estelle, Magali, Sandrine, Anne-Hélène, , Aurore, Véronique, Charlotte. Best of de notre magasin très révélateur du départemetn Loire-Atlantique : muscadet, bière, biscuits, légumes, rillettes...</strong></p> | D21: <p>Composition : Rillettes de canard les délices du petit gué (80g) Tartinable de légumes Papilles et petits plats (90g) Confiture de muroise (220g) Le sablé de la tarte bauloise (180g) Petit beurre artisanal à la fleur de sel fabriqué à Clisson par Maison Suzanne (80g) ,Vin blanc " La Mer " Domaine de la Fessardière (75cl) Bière de charlotte (75cl)</p> | E21: 132
A22: A-01978 | B22: Coffret Kir nantais | C22: <p><b>Une collection "Made In Nantes" avec des spécialités typiques. Muscadet et sirop le nantillais sont associés pour former le kir 100% Nantais et accompagnés de déclinaisons salées autour du muscadet : saucisse et canard et de quelques autres typicités dont le dessert historique au rhum, le gâteau nantais.</b></p> | D22: <p>Composition : Muscadet fruité et minéral, par la maison Cormerais, idéal pour l'apéritif et les crustacés à marier avec Nantillais : sirop sans alcool qui existe depuis plus de 20 ans. Salé : rillettes de canard au muscadet par Bérangère 100g, saucisse sèche au muscadet par le petit Landréen 150g environ, fleur de sel de la presqu'ile de Guérande 100g. Sucré : sachet de Berlingots aux fruits 200g et gâteau nantais 130g</p> | E22: 133
A23: A-05447 | B23: Coffret Lulu la Nantaise | C23: <p>LULU la nantaise, elle en buvait au petit-déjeuner... de la liqueur de petit beurre ?</p> | D23: <p>Déclinaison autour du petit beurre avec des biscuits faits maison, sa boite, une liqueur au goût de biscuit ainsi qu'une pâte à tartiner.</p> <p>Composition :</p> <ul style="list-style-type:disc;"><li>Liqueur au délicieux goût de biscuit à déguster seul ou en nappage (20cl)</li> <li>Petit beurre fabriqué avec amour à Clisson (44) au bon goût de beurre frais (70g)</li> <li>Boite à l'effigie du plus célèbre petit écolier du monde</li> <li>Dessous de verre LULU</li> <li>tablette chocolat petit beurre</li> </ul> | E23: 134
A24: A-01939 | B24: Whisky Nikka From The Barrel (blend) – Japon | D24: Bouteille iconique du groupe Nikka, le From The Barrel représente à lui seul la maîtrise de l’assemblage nippon : puissance, finesse et équilibre. Bluffant à plus d’un titre, ce blend aux 100 whiskies confondrait plus d’un amateur qui ne jure que par les single malts. Ici, les fruits bien mûrs, voire confits donnent le change à des épices de caractère. Le tout faisant passer les 51,4% d’alcool (presque) comme une lettre à la poste … L’art de l’assemblage avec un grand A | E24: 136
A25: A-01936 | B25: Whisky Nikka Coffey Grain (single grain) – Japon | D25: Elaboré à partir d’une majorité de maïs provenant des alambics « Coffey », ce single grain nous offre un aperçu des whiskies de grain qui forment la base de tous les blends de la maison Nikka, au style particulièrement suave et charmeur. | E25: 137
A26: A-01927 | B26: Whisky Kornog Roc'h Hir (tourbé) – Bretagne | D26: Whisky tourbé, mais d'une grande finesse, élevé en fut de bourbon. Meilleur Whisky Européen en 2016 par Jim MURRAY Liquid Gold Award 94/100 - Whisky Bible 2020 | E26: 138
A27: A-01895 | B27: Whisky Eddu Brocéliande pur blé noir – Bretagne | C27: <p>Fondée par la famille Le Lay qui était au départ dans les années 1920 des distillateurs ambulants et en 1986 ils créèrent "La distillerie des Menhirs". La distillerie familiale commença la réalisation du whisky en 1999 avec le premier du monde uniquement de blé noir.</p> | D27: <p>Vieilli d’abord 5 ans en fût de chêne français du Limousin, EDDU Silver Brocéliande achève sa maturation en fût de chêne neuf de la forêt de Brocéliande.</p> <p>Nez : boisé - floral - fruits secs</p> <p>Bouche : boisé - vanille - fruitées</p> <p>Finale : longue et raffinée </p> | E27: 139
A28: A-01894 | B28: Whisky Eddu Ed Gwenn (single malt) – Bretagne | C28: <p>Fondée par la famille Le Lay qui était au départ dans les années 1920 des distillateurs ambulants et en 1986 ils créèrent "La distillerie des Menhirs". La distillerie familiale commença la réalisation du whisky en 1999 avec le premier du monde uniquement de blé noir.</p> | D28: <p>Obtenu par distillation d’orge uniquement, Ed Gwenn est vieilli pendant plus de 4 ans en fûts de chêne français et américain. Par analogie avec Eddu qui signifie blé noir, Ed Gwenn signifie céréale blanche en breton.</p> <p>Nez : bananes flambées - fruits exotiques mûrs</p> <p>Bouche : litchi - pêche</p> <p>Finale : douce et élégante</p> | E28: 140
A29: A-01891 | B29: Whisky Eddu Gold 10 ans – Bretagne | C29: <p>Fondée par la famille Le Lay qui était au départ dans les années 1920 des distillateurs ambulants et en 1986 ils créèrent "La distillerie des Menhirs". La distillerie familiale commença la réalisation du whisky en 1999 avec le premier du monde uniquement de blé noir.</p> | D29: <p>Whisky vieillit 10 ans en fût de chêne français</p> <p>Nez : bois de chêne torréfié - épices</p> <p>Bouche : fruits pâtissiers - miel</p> <p>Finale : fruité - épices </p> | E29: 141
A30: A-01890 | B30: Whisky Eddu Silver 100 % blé noir – Bretagne | C30: <p>Fondée par la famille Le Lay qui était au départ dans les années 1920 des distillateurs ambulants et en 1986 ils créèrent "La distillerie des Menhirs". La distillerie familiale commença la réalisation du whisky en 1999 avec le premier du monde uniquement de blé noir.</p> | D30: <p>Vieilli 5 ans en fût de chêne français ayant contenu du Cognac, EDDU Silver l’original est la première édition de la gamme EDDU.</p> <p>Nez : agrumes - fruits frais - rose - bruyère</p> <p>bouche : pomme - épice - boisé très fin </p> <p>Finale : fraîche - fruité - équilibré</p> | E30: 142
A31: A-01760 | B31: Tête de Lard (cabernet franc) – Manoir de la Tête Rouge | C31: <p>Découvrez une appellation, un terroir et un vigneron au travers de cette cuvée en BIO DYNAMIE. 100% cabernet franc. 100% racé !</p> | D31: <p>Robe rouge Grenat, note de sous bois de torréfaction légèrement animal. La bouche est soyeuse vive complexe et riche. Les tannins sont présents granuleux sans astringence. La texture est crayeuse et la final est longue. Potentiel de garde de 10 ans, à 5 ans près !</p> | E31: 143
A32: A-01759 | B32: TÊTE D'ANGE (Chenin) - Manoir Tête Rouge | C32: <p><strong>Saumur blanc en biodynamie, élégance et terroir ! Un grand vigneron ! Vin blanc agréablement polyvalent : viande blanche, fromage, apéro...</strong></p> | D32: <p>Un joli chenin sur les terroirs de craies de Saumur. Le nez est sur la fleur blanche, la maturité du chenin est intense, des notes d’agrumes arrivent en final. En bouche, beaucoup de gras fait croire à du sucre résiduel mais le vin est sec.</p> | E32: 144
A33: A-02971 | B33: Rillettes de canard – Délices du Petit Gué 180 g | C33: <p><strong>Création locale et artisanale de Bérangère vers St Nazaire. Top qualité ! 180g</strong></p> <p><strong>ici au muscadet, existe aussi au sarrasin et muroise.</strong></p> | D33: <p>Petite entreprise artisanale, LES DELICES DU PETIT GUE est située à Frossay au sud-ouest de Nantes. Bérangère valorise les matières premières locales : canards élevés dans les communes alentour, Muscadet et Gros Plant du vignoble nantais, Coteaux du Layon, Muroise de Vallet et sel de Guérande.</p> | E33: 145
A34: A-02968 | B34: Rillettes de canard – Délices du Petit Gué 100 g | C34: <p>Petite entreprise artisanale, LES DELICES DU PETIT GUE est située à Frossay au sud-ouest de Nantes. Bérangère valorise les matières premières locales : canards élevés dans les communes alentour, Muscadet et Gros Plant du vignoble nantais, Coteaux du Layon, Muroise de Vallet et sel de Guérande.</p> | E34: 146
A35: A-01739 | B35: Terrine de porc – Papilles et Petits Plats 85 g | D35: <p>« Papilles et Petits Plats » est née en 2009 grâce aux délicieuses terrines que cuisinaient ses aïeuls. Depuis, Christine concocte pour vous tous les jours des terrines, des tartinables et des chutneys. Et bien sûr, les conserves « Papilles et Petits Plats » sont des produits artisanaux, locaux, sans additifs et de grande qualité ! Produits Made In Nantes.</p> | E35: 147
A36: A-03195 | B36: Tartinables de légumes – Papilles et Petits Plats | D36: <p>« Papilles et Petits Plats » est née en 2009 grâce aux délicieuses terrines que cuisinaient ses aïeuls. Depuis, Christine concocte pour vous tous les jours des terrines, des tartinables et des chutneys. Et bien sûr, les conserves « Papilles et Petits Plats » sont des produits artisanaux, locaux, sans additifs et de grande qualité ! Produits Made In Nantes.</p> | E36: 148
A37: A-03675 | B37: RILLETTES POISSONS DE LOIRE Claude janin | D37: <p>Claude Janin, artisan pêcheur basé à St-Juline-de-Concelles, prépare des terrines et des rillettes à base des poissons qu'il a lui même pêchés, produits qui sont labellisés « poisson sauvage du bassin de la Loire », ce qui assure la traçabilité sur la date et le lieu de pêche. Parfum : brochet beurre blanc, anguilles curé nantais, silure tomate...</p> | E37: 149
A38: A-01546 | B38: RHUM HAMPDEN 8 ans - Jamaïque | D38: Ce Hampden 8 ans, digne héritier des "Stinking Rums" Jamaïcains, est un savoureux mélange de fruits mûrs, d'épices douces et de notes finement boisées. Son profil intense et ses arômes très prononcés lui confèrent un caractère authentique et naturel. | E38: 150
A39: A-01509 | B39: Quernons d'Ardoise – boîte 60 g (x8) | C39: <p>Les Quernons d'Ardoise, la célèbre spécialité d'Angers : une fine nougatine enrobée de chocolat bleuté, en souvenir des ardoises de l'Anjou. Boîte de 8 pièces, jolie à offrir.</p> <p>Parfait au goûter, avec un café, ou pour garnir un coffret gourmand.</p> <p>Une question ? Nos cavistes vous conseillent volontiers en boutique ou au 02 40 89 76 26.</p> | D39: <p>Spécialité angevine gourmande sur une base nougatine et chocolat.</p> | E39: 152
A40: A-01507 | B40: QUERNONS BOITE 245g (x32) | D40: <p>Spécialité angevine gourmande sur une base nougatine et chocolat.</p> | E40: 153
...
